Workbook

Sheet Assumptions
B2: CITYCONNECT NYC — NEIGHBORHOOD NAVIGATOR | J2: x
B3: ASSUMPTIONS & DRIVERS | J3: x
B5: Scenario Chooser | D5: Base
D6: Bull
D7: Base
D8: Bear
B11: (A) TIMELINE | J11: x
B12: Year Label | D12: 1 | E12: =D12+1 -> 2 | F12: =E12+1 -> 3 | G12: =F12+1 -> 4 | H12: =G12+1 -> 5
B14: (B) OPERATING SCALE | J14: x
B15: Number of neighborhoods | D15: 3 | E15: 4 | F15: 5 | G15: 5 | H15: 5 | I15: Editable: pilot ramp
B16: Navigators per neighborhood | D16: 3 | E16: 4 | F16: 5 | G16: 5 | H16: 5 | I16: Editable per year
B17: Total navigators | D17: =D15*D16 -> 9 | E17: =E15*E16 -> 16 | F17: =F15*F16 -> 25 | G17: =G15*G16 -> 25 | H17: =H15*H16 -> 25
B18: Program managers | D18: 1 | E18: 1 | F18: 2 | G18: 2 | H18: 2 | I18: Add supervisor at 7+ sites
B19: Part-time admin/data support | D19: 1 | E19: 1 | F19: 2 | G19: 2 | H19: 2 | I19: Scale with sites
B20: Total FTE (central team) | D20: =D17+D18+D19 -> 11 | E20: =E17+E18+E19 -> 18 | F20: =F17+F18+F19 -> 29 | G20: =G17+G18+G19 -> 29 | H20: =H17+H18+H19 -> 29
B21: Total headcount (all staff) | D21: =D17+D20 -> 20 | E21: =E17+E20 -> 34 | F21: =F17+F20 -> 54 | G21: =G17+G20 -> 54 | H21: =H17+H20 -> 54
B23: (C) COMPENSATION | J23: x
B24: Navigator base salary (Year 1) | D24: =_xlfn.XLOOKUP($D$5,$D$6:$D$8,D25:D27) -> 32760 | I24: Annual base; grows with inflation
B25: Bull | D25: =17*7*260 -> 30940
B26: Base | D26: =18*7*260 -> 32760
B27: Bear | D27: =19*7*260 -> 34580
B28: Program manager salary (Year 1) | D28: =_xlfn.XLOOKUP($D$5,$D$6:$D$8,D29:D31) -> 41860
B29: Bull | D29: =22*7*260 -> 40040
B30: Base | D30: =23*7*260 -> 41860
B31: Bear | D31: =24*7*260 -> 43680
B32: Part-time admin salary (Year 1) | D32: =D28/2 -> 20930 | I32: 0.5 FTE equivalent
B33: Fringe benefits rate | D33: 0.25 | I33: Health, FICA, retirement, etc.
B34: Annual salary inflation / raises | D34: 0.03 | I34: Applied to all salaries Year 2+
B35: Navigator salary by year | D35: =D24 -> 32760 | E35: =D35*(1+$D$34) -> 33742.8 | F35: =E35*(1+$D$34) -> 34755.084 | G35: =F35*(1+$D$34) -> 35797.737 | H35: =G35*(1+$D$34) -> 36871.669
B36: PM salary by year | D36: =D28 -> 41860 | E36: =D36*(1+$D$34) -> 43115.8 | F36: =E36*(1+$D$34) -> 44409.274 | G36: =F36*(1+$D$34) -> 45741.552 | H36: =G36*(1+$D$34) -> 47113.799
B37: Admin salary by year | D37: =D32 -> 20930 | E37: =D37*(1+$D$34) -> 21557.9 | F37: =E37*(1+$D$34) -> 22204.637 | G37: =F37*(1+$D$34) -> 22870.776 | H37: =G37*(1+$D$34) -> 23556.899
B39: (D) NON-LABOR COSTS | J39: x
B40: Non-labor cost per neighborhood per year | D40: =_xlfn.XLOOKUP($D$5,$D$6:$D$8,D41:D43) -> 15750 | I40: Space fee, supplies, outreach
B41: Bull | D41: 15000
B42: Base | D42: =D41*1.05 -> 15750
B43: Bear | D43: =D42*1.05 -> 16537.5
B44: Tech/CRM fixed annual cost | D44: =_xlfn.XLOOKUP($D$5,$D$6:$D$8,D45:D47) -> 10500 | I44: Platform license / hosting
B45: Bull | D45: 10000
B46: Base | D46: =D45*1.05 -> 10500
B47: Bear | D47: =D46*1.05 -> 11025
...

Sheet 5Y Projection
B2: CITYCONNECT NYC — NEIGHBORHOOD NAVIGATOR | J2: x
B3: 5-YEAR STATEMENT OF ACTIVITIES PROJECTION | J3: x
B5: Scenario | D5: =Assumptions!D5 -> Base
D7: =Assumptions!D12 -> 1 | E7: =Assumptions!E12 -> 2 | F7: =Assumptions!F12 -> 3 | G7: =Assumptions!G12 -> 4 | H7: =Assumptions!H12 -> 5 | I7: Notes
B8: OPERATING SCALE | J8: x
B9: Sites | D9: =Assumptions!D15 -> 3 | E9: =Assumptions!E15 -> 4 | F9: =Assumptions!F15 -> 5 | G9: =Assumptions!G15 -> 5 | H9: =Assumptions!H15 -> 5
B10: Total navigators | D10: =Assumptions!D17 -> 9 | E10: =Assumptions!E17 -> 16 | F10: =Assumptions!F17 -> 25 | G10: =Assumptions!G17 -> 25 | H10: =Assumptions!H17 -> 25
B11: Total headcount | D11: =Assumptions!D21 -> 20 | E11: =Assumptions!E21 -> 34 | F11: =Assumptions!F21 -> 54 | G11: =Assumptions!G21 -> 54 | H11: =Assumptions!H21 -> 54
B13: OPERATING REVENUE | J13: x
B14: Government grants & contracts | D14: =Assumptions!D64 -> 600000 | E14: =Assumptions!D64/Assumptions!D15*Assumptions!E15*(1+Assumptions!E64) -> 960000 | F14: =Assumptions!D64/Assumptions!D15*Assumptions!F15*(1+Assumptions!E64)^2 -> 1440000 | G14: =Assumptions!D64/Assumptions!D15*Assumptions!G15*(1+Assumptions!E64)^3 -> 1728000 | H14: =Assumptions!D64/Assumptions!D15*Assumptions!H15*(1+Assumptions!E64)^4 -> 2073600 | I14: Scales with sites + 10% growth
B15: Foundation grants | D15: =Assumptions!D68 -> 240000 | E15: =D15*(1+Assumptions!E68) -> 276000 | F15: =E15*(1+Assumptions!E68) -> 317400 | G15: =F15*(1+Assumptions!E68) -> 365010 | H15: =G15*(1+Assumptions!E68) -> 419761.5 | I15: 15% annual growth
B16: Individual contributions | D16: =Assumptions!D72 -> 55000 | E16: =D16*(1+Assumptions!E72) -> 71500 | F16: =E16*(1+Assumptions!E72) -> 92950 | G16: =F16*(1+Assumptions!E72) -> 120835 | H16: =G16*(1+Assumptions!E72) -> 157085.5 | I16: 20% annual growth
B17: Corporate/CSR contributions | D17: =Assumptions!D76 -> 55000 | E17: =D17*(1+Assumptions!E76) -> 63250 | F17: =E17*(1+Assumptions!E76) -> 72737.5 | G17: =F17*(1+Assumptions!E76) -> 83648.125 | H17: =G17*(1+Assumptions!E76) -> 96195.344 | I17: 15% annual growth
B18: Other income | D18: =Assumptions!D80 -> 20000 | E18: =D18*(1+Assumptions!E80) -> 21000 | F18: =E18*(1+Assumptions!E80) -> 22050 | G18: =F18*(1+Assumptions!E80) -> 23152.5 | H18: =G18*(1+Assumptions!E80) -> 24310.125
B20: Total Operating Revenue | D20: =SUM(D14:D18) -> 970000 | E20: =SUM(E14:E18) -> 1391750 | F20: =SUM(F14:F18) -> 1945137.5 | G20: =SUM(G14:G18) -> 2320645.6 | H20: =SUM(H14:H18) -> 2770952.5
B22: OPERATING EXPENSES | J22: x
B23: Program Services (detail)
B24: Navigator compensation | D24: =Assumptions!D17*Assumptions!D35*(1+Assumptions!D33) -> 368550 | E24: =Assumptions!E17*Assumptions!E35*(1+Assumptions!D33) -> 674856 | F24: =Assumptions!F17*Assumptions!F35*(1+Assumptions!D33) -> 1086096.4 | G24: =Assumptions!G17*Assumptions!G35*(1+Assumptions!D33) -> 1118679.3 | H24: =Assumptions!H17*Assumptions!H35*(1+Assumptions!D33) -> 1152239.6 | I24: Navigators × salary × (1+fringe)
B25: Program manager compensation | D25: =Assumptions!D18*Assumptions!D36*(1+Assumptions!D33) -> 52325 | E25: =Assumptions!E18*Assumptions!E36*(1+Assumptions!D33) -> 53894.75 | F25: =Assumptions!F18*Assumptions!F36*(1+Assumptions!D33) -> 111023.19 | G25: =Assumptions!G18*Assumptions!G36*(1+Assumptions!D33) -> 114353.88 | H25: =Assumptions!H18*Assumptions!H36*(1+Assumptions!D33) -> 117784.5 | I25: PMs × salary × (1+fringe)
B26: Admin/data support compensation | D26: =Assumptions!D19*Assumptions!D37*(1+Assumptions!D33) -> 26162.5 | E26: =Assumptions!E19*Assumptions!E37*(1+Assumptions!D33) -> 26947.375 | F26: =Assumptions!F19*Assumptions!F37*(1+Assumptions!D33) -> 55511.593 | G26: =Assumptions!G19*Assumptions!G37*(1+Assumptions!D33) -> 57176.94 | H26: =Assumptions!H19*Assumptions!H37*(1+Assumptions!D33) -> 58892.248 | I26: Admin × salary × (1+fringe)
B27: Non-labor program costs | D27: =Assumptions!D15*Assumptions!D40 -> 47250 | E27: =Assumptions!E15*Assumptions!D40*(1+Assumptions!D56) -> 64260 | F27: =Assumptions!F15*Assumptions!D40*(1+Assumptions!D56)^2 -> 81931.5 | G27: =Assumptions!G15*Assumptions!D40*(1+Assumptions!D56)^3 -> 83570.13 | H27: =Assumptions!H15*Assumptions!D40*(1+Assumptions!D56)^4 -> 85241.533 | I27: Sites × cost/site (inflated)
B28: Technology / CRM | D28: =Assumptions!D44+Assumptions!D17*Assumptions!D48 -> 19950 | E28: =Assumptions!D44+Assumptions!E17*Assumptions!D48 -> 27300 | F28: =Assumptions!D44+Assumptions!F17*Assumptions!D48 -> 36750 | G28: =Assumptions!D44+Assumptions!G17*Assumptions!D48 -> 36750 | H28: =Assumptions!D44+Assumptions!H17*Assumptions!D48 -> 36750 | I28: Fixed + per-navigator variable
B29: Marketing / outreach | D29: =Assumptions!D15*Assumptions!D52 -> 15750 | E29: =Assumptions!E15*Assumptions!D52*(1+Assumptions!D56) -> 21420 | F29: =Assumptions!F15*Assumptions!D52*(1+Assumptions!D56)^2 -> 27310.5 | G29: =Assumptions!G15*Assumptions!D52*(1+Assumptions!D56)^3 -> 27856.71 | H29: =Assumptions!H15*Assumptions!D52*(1+Assumptions!D56)^4 -> 28413.844 | I29: Sites × outreach/site (inflated)
B30: Startup costs | D30: =Assumptions!D57 -> 15750 | E30: 0 | F30: 0 | G30: 0 | H30: 0 | I30: Year 1 only
B32: Total Program Services | D32: =SUM(D24:D30) -> 545737.5 | E32: =SUM(E24:E30) -> 868678.12 | F32: =SUM(F24:F30) -> 1398623.2 | G32: =SUM(G24:G30) -> 1438386.9 | H32: =SUM(H24:H30) -> 1479321.8
B34: Management & General | D34: =D32*Assumptions!D83/(1-Assumptions!D83) -> 60637.5 | E34: =E32*Assumptions!D83/(1-Assumptions!D83) -> 96519.792 | F34: =F32*Assumptions!D83/(1-Assumptions!D83) -> 155402.57 | G34: =G32*Assumptions!D83/(1-Assumptions!D83) -> 159820.77 | H34: =H32*Assumptions!D83/(1-Assumptions!D83) -> 164369.09 | I34: Prog x MG%/(1-MG%); no circular ref
B36: Fundraising
B37: Private contributions subtotal | D37: =D15+D16+D17 -> 350000 | E37: =E15+E16+E17 -> 410750 | F37: =F15+F16+F17 -> 483087.5 | G37: =G15+G16+G17 -> 569493.12 | H37: =H15+H16+H17 -> 673042.34 | I37: Foundation + Individual + Corporate
B38: Fundraising Expense | D38: =D37*Assumptions!$D$87 -> 42000 | E38: =E37*Assumptions!$D$87 -> 49290 | F38: =F37*Assumptions!$D$87 -> 57970.5 | G38: =G37*Assumptions!$D$87 -> 68339.175 | H38: =H37*Assumptions!$D$87 -> 80765.081 | I38: 12% of private contributions
B40: Total Operating Expenses | D40: =D32+D34+D38 -> 648375 | E40: =E32+E34+E38 -> 1014487.9 | F40: =F32+F34+F38 -> 1611996.2 | G40: =G32+G34+G38 -> 1666546.9 | H40: =H32+H34+H38 -> 1724455.9
B42: SURPLUS / (DEFICIT) | J42: x
B43: Change in Net Assets | D43: =D20-D40 -> 321625 | E43: =E20-E40 -> 377262.08 | F43: =F20-F40 -> 333141.27 | G43: =G20-G40 -> 654098.75 | H43: =H20-H40 -> 1046496.5 | I43: Revenue - Expenses
B45: Operating Margin % | D45: =IF(D20=0,0,D43/D20) -> 0.33157216 | E45: =IF(E20=0,0,E43/E20) -> 0.2710703 | F45: =IF(F20=0,0,F43/F20) -> 0.17126875 | G45: =IF(G20=0,0,G43/G20) -> 0.28186068 | H45: =IF(H20=0,0,H43/H20) -> 0.37766672
B47: Total Net Assets | D47: =D43 -> 321625 | E47: =D47+E43 -> 698887.08 | F47: =E47+F43 -> 1032028.4 | G47: =F47+G43 -> 1686127.1 | H47: =G47+H43 -> 2732623.6
B49: REASONABLENESS CHECKS | J49: x
B50: Program Services % of Total Expenses | D50: =IF(D40=0,0,D32/D40) -> 0.8417004 | E50: =IF(E40=0,0,E32/E40) -> 0.85627252 | F50: =IF(F40=0,0,F32/F40) -> 0.86763426 | G50: =IF(G40=0,0,G32/G40) -> 0.86309419 | H50: =IF(H40=0,0,H32/H40) -> 0.8578484 | I50: Target: 75-90%
B51: Private Contributions % of Total Revenue | D51: =IF(D20=0,0,D37/D20) -> 0.36082474 | E51: =IF(E20=0,0,E37/E20) -> 0.29513203 | F51: =IF(F20=0,0,F37/F20) -> 0.24835648 | G51: =IF(G20=0,0,G37/G20) -> 0.24540288 | H51: =IF(H20=0,0,H37/H20) -> 0.24289206 | I51: Revenue diversification check
B52: Government Revenue % of Total | D52: =IF(D20=0,0,D14/D20) -> 0.6185567 | E52: =IF(E20=0,0,E14/E20) -> 0.68977906 | F52: =IF(F20=0,0,F14/F20) -> 0.74030756 | G52: =IF(G20=0,0,G14/G20) -> 0.74462037 | H52: =IF(H20=0,0,H14/H20) -> 0.74833474 | I52: Government dependency check
B54: MODEL LOGIC NOTES
B55: 1. Revenue: Government grants scale with # of neighborhoods (per-neighborhood contract model) plus 20% annual growth. Private revenue grows at fixed annual rates (Foundation 15%, Individual 30%, Corporate 15%).
...
